Workbook

Sheet Dashboard
A3: 1. High-Level KPIs : | C3: TOTAL TRACKED EMBASSIES (Unique IDs) | G3: ACTIVE ENGAGEMENT RATE (Embassies classified as 'Engaged' or 'In Discussion') | K3: OUTREACH REQUIRING ACTION (Embassies classified as 'On Hold' or 'Not Started' or 'Meeting Scheduled')
C4: {=COUNTA(_xlfn.UNIQUE(_xlfn._xlws.FILTER('BackEnd Data'!A2:A89,'BackEnd Data'!A2:A89<>"")))} -> 85 | G4: =(C10+C12)/SUM(C10:C16) -> 0.40909091 | K4: =(C14+C15+C13)/SUM(C10:C16) -> 0.36363636
B7: 2. Outreach Status Distribution | H7: 3. Regional Engagement Breakdown | O7: 4. Engagement Level | S7: 5. MANAGEMENT ATTENTION
B9: Outreach Status | C9: Count | D9: % Share | H9: Region | I9: Total Embassies | J9: Engaged | K9: In Discussion | L9: Active Engagement Rate | O9: Engagement Level | P9: Count | S9: Issue | T9: Records Requiring Attention
B10: Engaged | C10: =COUNTIF('BackEnd Data'!H:H, "Engaged") -> 22 | D10: =ROUND(C10/SUM($C$10:$C$16),2) -> 0.25 | H10: Europe | I10: =COUNTIF('BackEnd Data'!C1:C89, "Europe") -> 19 | J10: =COUNTIFS('BackEnd Data'!$C$2:$C$92,"Europe",'BackEnd Data'!$H$2:$H$92,"Engaged") -> 3 | K10: =COUNTIFS('BackEnd Data'!$C$2:$C$92,"Europe",'BackEnd Data'!$H$2:$H$92,"In Discussion") -> 4 | L10: =(COUNTIFS('BackEnd Data'!$C$2:$C$92,"Europe",'BackEnd Data'!$H$2:$H$92,"Engaged")+COUNTIFS('BackEnd Data'!$C$2:$C$92,"Europe",'BackEnd Data'!$H$2:$H$92,"In Discussion"))/COUNTIF('BackEnd Data'!$C$2:$C$92,"Europe") -> 0.36842105 | O10: Low | P10: =COUNTIF('BackEnd Data'!N2:N92, "Low") -> 26 | S10: Missing Next Follow-up | T10: =COUNTBLANK('BackEnd Data'!$L$2:$L$92) -> 25
B11: Initial Contact Made | C11: =COUNTIF('BackEnd Data'!H:H, "Initial Contact Made") -> 15 | D11: =ROUND(C11/SUM($C$10:$C$16),2) -> 0.17 | H11: Sub-Saharan Africa | I11: =COUNTIF('BackEnd Data'!C1:C89, "Sub-Saharan Africa") -> 16 | J11: =COUNTIFS('BackEnd Data'!$C$2:$C$92,"Sub-Saharan Africa",'BackEnd Data'!$H$2:$H$92,"Engaged") -> 7 | K11: =COUNTIFS('BackEnd Data'!$C$2:$C$92,"Sub-Saharan Africa",'BackEnd Data'!$H$2:$H$92,"In Discussion") -> 2 | L11: =(COUNTIFS('BackEnd Data'!$C$2:$C$92,"Sub-Saharan Africa",'BackEnd Data'!$H$2:$H$92,"Engaged")+COUNTIFS('BackEnd Data'!$C$2:$C$92,"Sub-Saharan Africa",'BackEnd Data'!$H$2:$H$92,"In Discussion"))/COUNTIF('BackEnd Data'!$C$2:$C$92,"Sub-Saharan Africa") -> 0.5625 | O11: Medium | P11: =COUNTIF('BackEnd Data'!N2:N92, "Medium") -> 22 | S11: Missing Engagement Level | T11: =COUNTBLANK('BackEnd Data'!$N$2:$N$92) -> 24
B12: In Discussion | C12: =COUNTIF('BackEnd Data'!H:H, "In Discussion") -> 14 | D12: =ROUND(C12/SUM($C$10:$C$16),2) -> 0.16 | H12: Asia-Pacific | I12: =COUNTIF('BackEnd Data'!C3:C91, "Asia-Pacific") -> 15 | J12: =COUNTIFS('BackEnd Data'!$C$2:$C$92,"Asia-Pacific",'BackEnd Data'!$H$2:$H$92,"Engaged") -> 3 | K12: =COUNTIFS('BackEnd Data'!$C$2:$C$92,"Asia-Pacific",'BackEnd Data'!$H$2:$H$92,"In Discussion") -> 4 | L12: =(COUNTIFS('BackEnd Data'!$C$2:$C$92,"Asia-Pacific",'BackEnd Data'!$H$2:$H$92,"Engaged")+COUNTIFS('BackEnd Data'!$C$2:$C$92,"Asia-Pacific",'BackEnd Data'!$H$2:$H$92,"In Discussion"))/COUNTIF('BackEnd Data'!$C$2:$C$92,"Asia-Pacific") -> 0.46666667 | O12: High | P12: =COUNTIF('BackEnd Data'!N3:N93, "High") -> 19 | S12: Missing Owner | T12: =COUNTBLANK('BackEnd Data'!$J$2:$J$92) -> 13
B13: Meeting Scheduled | C13: =COUNTIF('BackEnd Data'!H:H, "Meeting Scheduled") -> 11 | D13: =ROUND(C13/SUM($C$10:$C$16),2) -> 0.13 | H13: America | I13: =COUNTIF('BackEnd Data'!C4:C92, "America") -> 14 | J13: =COUNTIFS('BackEnd Data'!$C$2:$C$92,"America",'BackEnd Data'!$H$2:$H$92,"Engaged") -> 4 | K13: =COUNTIFS('BackEnd Data'!$C$2:$C$92,"America",'BackEnd Data'!$H$2:$H$92,"In Discussion") -> 1 | L13: =(COUNTIFS('BackEnd Data'!$C$2:$C$92,"America",'BackEnd Data'!$H$2:$H$92,"Engaged")+COUNTIFS('BackEnd Data'!$C$2:$C$92,"America",'BackEnd Data'!$H$2:$H$92,"In Discussion"))/COUNTIF('BackEnd Data'!$C$2:$C$92,"America") -> 0.35714286 | O13: Unknown/Missing | P13: =COUNTIF('BackEnd Data'!N3:N93, "") -> 24 | S13: Missing Email | T13: =COUNTBLANK('BackEnd Data'!$F$2:$F$89) -> 7
B14: On Hold | C14: =COUNTIF('BackEnd Data'!H:H, "On Hold") -> 11 | D14: =ROUND(C14/SUM($C$10:$C$16),2) -> 0.13 | H14: Middle East & North Africa | I14: =COUNTIF('BackEnd Data'!C5:C93, "Middle East & North Africa") -> 12 | J14: =COUNTIFS('BackEnd Data'!$C$2:$C$92,"Middle East & North Africa",'BackEnd Data'!$H$2:$H$92,"Engaged") -> 4 | K14: =COUNTIFS('BackEnd Data'!$C$2:$C$92,"Middle East & North Africa",'BackEnd Data'!$H$2:$H$92,"In Discussion") -> 2 | L14: =(COUNTIFS('BackEnd Data'!$C$2:$C$92,"Middle East & North Africa",'BackEnd Data'!$H$2:$H$92,"Engaged")+COUNTIFS('BackEnd Data'!$C$2:$C$92,"Middle East & North Africa",'BackEnd Data'!$H$2:$H$92,"In Discussion"))/COUNTIF('BackEnd Data'!$C$2:$C$92,"Middle East & North Africa") -> 0.5 | S14: Missing Phone | T14: =COUNTBLANK('BackEnd Data'!$I$2:$I$89) -> 8
B15: Not Started | C15: =COUNTIF('BackEnd Data'!H:H, "Not Started") -> 10 | D15: =ROUND(C15/SUM($C$10:$C$16),2) -> 0.11 | H15: South & Central Asia | I15: =COUNTIF('BackEnd Data'!C6:C94, "South & Central Asia") -> 7 | J15: =COUNTIFS('BackEnd Data'!$C$2:$C$92,"South & Central Asia",'BackEnd Data'!$H$2:$H$92,"Engaged") -> 1 | K15: =COUNTIFS('BackEnd Data'!$C$2:$C$92,"South & Central Asia",'BackEnd Data'!$H$2:$H$92,"In Discussion") -> 1 | L15: =(COUNTIFS('BackEnd Data'!$C$2:$C$92,"South & Central Asia",'BackEnd Data'!$H$2:$H$92,"South & Central Asia")+COUNTIFS('BackEnd Data'!$C$2:$C$92,"Europe",'BackEnd Data'!$H$2:$H$92,"In Discussion"))/COUNTIF('BackEnd Data'!$C$2:$C$92,"South & Central Asia") -> 0.57142857 | S15: Date / Data Consistency Issues | T15: =8 -> 8
B16: Closed | C16: =COUNTIF('BackEnd Data'!H:H, "Closed") -> 5 | D16: =ROUND(C16/SUM($C$10:$C$16),2) -> 0.06 | H16: Unknown/Missing | I16: =COUNTBLANK('BackEnd Data'!$C$2:$C$89) -> 5 | J16: =COUNTIFS('BackEnd Data'!$C$2:$C$92,"",'BackEnd Data'!$H$2:$H$92,"Engaged") -> 0 | K16: =COUNTIFS('BackEnd Data'!$C$2:$C$92,"",'BackEnd Data'!$H$2:$H$92,"In Discussion") -> 0 | L16: =(J16+K16)/COUNT('BackEnd Data'!N1:N90) -> #DIV/0! | S16: Invalid Interaction Count | T16: =COUNTIF('BackEnd Data'!$M$2:$M$89,"<0") -> 1
H17: Total | I17: =SUM(I10:I16) -> 88 | J17: =SUM(J10:J16) -> 22 | K17: =SUM(K10:K16) -> 14 | L17: =SUM(L10:L15) -> 2.8261591
B18: Total | C18: =SUM(C10:C16) -> 88 | D18: =SUM(C10:C16)/SUM(C10:C16) -> 1

Sheet BackEnd Data
A1: Embassy ID | B1: Country | C1: Region | D1: Contact Person | E1: Designation | F1: Email | G1: Phone | H1: Outreach Status | I1: Outreach Owner | J1: First Contact Date | K1: Last Contact Date | L1: Next Followup Date | M1: Interactions | N1: Engagement Level | O1: Channel | P1: Remarks
A2: EMB-001 | B2: France | C2: Europe | D2: Mei Schmidt | E2: Counsellor (Public Affairs) | F2: mei.schmidt@france.embassy.example | G2: +91 91399 86987 | H2: Not started | I2: Neha Kulkarni | M2: 0 | P2: Priority list - Q4
A3: EMB-002 | B3: Germany | C3: Europe | D3: Stefan Haddad | E3: Commercial Counsellor | F3: stefan.haddad@germany.embassy.example | G3: 911181707536 | H3: Initial Contact Made | I3: Priya Nair | J3: 46057 | K3: 46078 | L3: 46132 | M3: 1 | N3: Low | O3: Email | P3: Intro call held
A4: EMB-003 | B4: Italy | D4: Kwame Okafor | E4: Counsellor (Public Affairs) | F4: kwame.okafor@italy.embassy.example | G4: +91 11 2698 7168 | H4: On Hold | I4: Neha Kulkarni | J4: 46079 | K4: 46143 | L4: 46257 | M4: 6 | O4: Phone | P4: Awaiting HQ approval
A5: EMB-004 | B5: Spain | C5: Europe | D5: Leila Bergstrom | E5: Protocol Officer | F5: leila.bergstrom@spain.embassy.example | G5: +91 11 3731 7784 | H5: Engaged | I5: Sameer Khan | J5: 46233 | K5: 46248 | L5: 46287 | M5: 19 | N5: High | O5: Phone | P5: Regular quarterly touchpoints
A6: EMB-005 | B6: Portugal | C6: Europe | D6: Omar Khalil | E6: Counsellor (Public Affairs) | F6: omar.khalil@portugal.embassy.example | G6: +91 97876 80457 | H6: In Discussion | I6: Anita Deshmukh | J6: 46199 | K6: 46270 | L6: 46295 | M6: 8 | N6: Low | O6: Official Letter | P6: Positive response
A7: EMB-006 | B7: Netherlands | C7: Europe | D7: Carla Alvarez | E7: Counsellor (Public Affairs) | F7: carla.alvarez@netherlands.embassy.example | G7: +91 11 8193 3190 | H7: Not started | I7: Neha Kulkarni | K7: 46249 | M7: 2 | P7: Contact details to be verified
A8: EMB-007 | B8: Belgium | C8: Europe | D8: Amara Okafor | E8: Protocol Officer | F8: amara.okafor@belgium.embassy.example | G8: +91 11 4997 2837 | H8: Engaged | I8: Rahul Verma | J8: 45758 | K8: 46294 | L8: 46316 | N8: Medium | O8: Event | P8: Regular quarterly touchpoints
A9: EMB-008 | B9: Switzerland | C9: Europe | D9: Elena Rossi | E9: Protocol Officer | F9: elena.rossi@switzerland.embassy.example | G9: +91 11 4475 1779 | H9: Meeting Scheduled | I9: Rahul Verma | J9: 46204 | K9: 46280 | O9: Official Letter | P9: Meeting with Ambassador pending
A10: EMB-009 | B10: Austria | C10: Europe | D10: Amara Petrov | E10: Second Secretary | G10: +91 11 7028 3 | H10: Not started | M10: 0 | P10: Priority list - Q4
A11: EMB-010 | B11: Sweden | C11: Europe | D11: Joao Garcia | E11: Commercial Counsellor | F11: joao.garcia@sweden.embassy.example | G11: +91 96425 24776 | H11: Initial Contact Made | I11: Sameer Khan | J11: 46005 | M11: 2 | N11: Medium | O11: Event | P11: Awaiting acknowledgement
A12: EMB-011 | B12: Norway | C12: Europe | D12: Diego Mensah | E12: Second Secretary | F12: diego.mensah@norway.embassy.example | G12: +91 95258 98319 | H12: On Hold | I12: Priya Nair | J12: 45891 | K12: 46233 | L12: 46310 | M12: 2 | N12: Low | O12: Email | P12: Paused - elections
A13: EMB-012 | B13: Denmark | C13: Europe | D13: Mei Moreau | E13: First Secretary (Political) | F13: mei.moreau@denmark.embassy.example | G13: +91 11 8145 2441 | H13: Meeting Scheduled | I13: Sameer Khan | J13: 46096 | K13: 46195 | L13: 46215 | M13: 6 | N13: Medium | O13: Email | P13: Date to be confirmed
A14: EMB-013 | B14: Finland | C14: Europe | D14: Stefan Petrov | E14: First Secretary (Political) | F14: stefan.petrov@finland.embassy.example | G14: +91 11 5158 4645 | H14: In Discussion | I14: Arjun Mehta | J14: 45696 | K14: 46289 | L14: 46321 | M14: 5 | N14: Medium | O14: Email | P14: Positive response
A15: EMB-014 | B15: Poland | C15: Europe | D15: Aisha Tanaka | E15: Press & Information Officer | F15: aisha.tanaka@poland.embassy.example | G15: +91 11 4940 6925 | H15: Meeting Scheduled | I15: Sameer Khan | J15: 45917 | K15: 46383 | M15: 8 | N15: Medium | O15: Phone | P15: Date to be confirmed
A16: EMB-015 | B16: Czechia | C16: Europe | D16: Sofia Larsen | E16: Counsellor (Public Affairs) | F16: sofia.larsen@czechrepubli.embassy.example | G16: +91 99128 08458 | H16: In Discussion | I16: Arjun Mehta | J16: 45729 | K16: 46269 | L16: 46323 | M16: 6 | N16: High | O16: Official Letter | P16: Reviewing MoU wording
A17: EMB-016 | B17: Hungary | C17: Europe | D17: Fatima Moreau | E17: Cultural Attache | F17: fatima.moreau@hungary.embassy.example | H17: Initial Contact Made | I17: Arjun Mehta | J17: 45829 | K17: 46299 | M17: 2 | N17: Low | O17: Official Letter | P17: Note verbale sent
A18: EMB-017 | B18: Greece | D18: Omar Alvarez | E18: First Secretary (Political) | F18: omar.alvarez@greece.embassy.example | G18: +91 11 2668 8281 | H18: Not started | I18: Rahul Verma | M18: 0 | P18: Priority list - Q4
A19: EMB-018 | B19: Ireland | C19: Europe | D19: Fatima Novak | E19: Cultural Attache | F19: fatima.novak@ireland.embassy.example | G19: +91 11 6324 4845 | H19: In Discussion | I19: Sameer Khan | J19: 45681 | K19: 46087 | L19: 46128 | M19: 0 | N19: Medium | O19: Phone | P19: Draft proposal shared
A20: EMB-019 | B20: UK | C20: Europe | D20: Amara Rossi | E20: Cultural Attache | F20: amara.rossi@unitedkingdo.embassy.example | G20: +91 91543 82993 | H20: On Hold | I20: Anita Deshmukh | J20: 46168 | K20: 46273 | L20: 46379 | M20: 4 | N20: Low | O20: Event | P20: Awaiting HQ approval
A21: EMB-020 | B21: Russian Federation | C21: Europe | D21: Carla Alvarez | E21: Press & Information Officer | F21: carla.alvarez@russia.embassy.example | G21: +91 11 2174 4325 | H21: Engaged | I21: Neha Kulkarni | J21: 46002 | K21: 46083 | L21: 46122 | M21: 18 | N21: High | O21: Event | P21: Regular quarterly touchpoints
A22: EMB-021 | B22: Japan | D22: Omar Larsen | E22: Counsellor (Public Affairs) | F22: omar.larsen@japan.embassy.example | G22: +91 11 6264 5154 | H22: Meeting Scheduled | I22: Sameer Khan | J22: 45820 | K22: 46252 | L22: 46280 | M22: 8 | N22: Medium | O22: Meeting | P22: Date to be confirmed
A23: EMB-022 | B23: Korea (South) | C23: Asia-Pacific | D23: Sofia Silva | E23: Second Secretary | F23: sofia.silva@southkorea.embassy.example | G23: +91 97883 65506 | H23: Engaged | I23: Rahul Verma | J23: 45945 | K23: 46253 | L23: 46275 | M23: 0 | O23: Meeting | P23: Embassy declined further participation
A24: EMB-023 | B24: China | C24: Asia-Pacific | D24: Fatima Moreau | E24: Second Secretary | F24: fatima.moreau@china.embassy.example | G24: +91 11 3784 9518 | H24: Engaged | I24: Rahul Verma | J24: 45769 | K24: 46292 | L24: 46335 | M24: 8 | N24: High | O24: Email | P24: Active collaboration
A25: EMB-024 | B25: Indonesia | C25: Asia-Pacific | D25: Andrei Tanaka | E25: Protocol Officer | F25: andrei.tanaka@indonesia.embassy.example | G25: +91 11 7837 5555 | H25: Initial Contact Made | J25: 46172 | K25: 46173 | L25: 46228 | M25: 2 | N25: Medium | O25: Meeting | P25: Intro call held
A26: EMB-025 | B26: Malaysia | C26: Asia-Pacific | D26: Nadia Tanaka | E26: Protocol Officer | F26: nadia.tanaka@malaysia.embassy.example | G26: +91 91884 79 | H26: Initial Contact Made | I26: Priya Nair | J26: 45997 | K26: 46246 | L26: 46271 | M26: 1 | N26: Medium | O26: Meeting | P26: Note verbale sent
A27: EMB-026 | B27: Singapore | C27: Asia-Pacific | D27: Omar Rossi | E27: Counsellor (Public Affairs) | F27: omar.rossi@singapore.embassy.example | G27: +91 11 3688 2834 | H27: Closed | I27: Arjun Mehta | J27: 45811 | K27: 46216 | M27: 2 | N27: Low | O27: Email | P27: Declined - policy restrictions
A28: EMB-027 | B28: Thailand | C28: Asia-Pacific | D28: Diego Alvarez | E28: Second Secretary | F28: diego.alvarez@thailand.embassy.example | G28: +91 11 7044 2248 | H28: Engaged | I28: Priya Nair | J28: 46140 | K28: 46277 | L28: 46294 | M28: 12 | N28: High | O28: Event | P28: Co-hosted event in Q2
A29: EMB-028 | B29: Vietnam | C29: Asia-Pacific | D29: Diego Garcia | E29: Commercial Counsellor | F29: diego.garcia@vietnam.embassy.example | G29: +91 11 4280 7001 | H29: Not started | I29: Neha Kulkarni | K29: 46199 | M29: 1 | P29: Contact details to be verified
A30: EMB-029 | B30: Philippines | C30: Asia-Pacific | D30: Elena Mensah | E30: Second Secretary | F30: elena.mensah@philippines.embassy.example | G30: +91 11 8166 3233 | H30: In Discussion | I30: Sameer Khan | J30: 46053 | K30: 46272 | L30: 46313 | M30: 6 | N30: Medium | O30: Email | P30: Draft proposal shared
A31: EMB-030 | B31: Australia | C31: Asia-Pacific | D31: Pavel Petrov | E31: Cultural Attache | F31: pavel.petrov@australia.embassy.example | G31: +91 11 2592 1236 | H31: On Hold | I31: Sameer Khan | J31: 46232 | K31: 46241 | L31: 46348 | M31: 6 | N31: Low | O31: Event | P31: Embassy leadership change
A32: EMB-031 | B32: New Zealand | C32: Asia-Pacific | D32: Kwame Yilmaz | E32: Press & Information Officer | F32: kwame.yilmaz@newzealand.embassy.example | G32: +91 11 7908 5417 | H32: Meeting Scheduled | I32: Priya Nair | J32: 46210 | K32: 46218 | L32: 46250 | M32: 8 | O32: Phone | P32: Venue finalised
A33: EMB-032 | B33: Mongolia | C33: Asia-Pacific | D33: Elena Larsen | E33: First Secretary (Political) | F33: elena.larsen@mongolia.embassy.example | G33: +91 92016 12840 | H33: In Discussion | I33: Arjun Mehta | J33: 46205 | L33: 46307 | M33: 5 | N33: Medium | O33: Phone | P33: Exploring joint programme
A34: EMB-033 | B34: Myanmar | C34: Asia-Pacific | D34: Stefan Mensah | E34: First Secretary (Political) | F34: stefan.mensah@myanmar | G34: +91 11 8197 9678 | H34: in discussion | I34: Sameer Khan | J34: 46065 | K34: 46236 | L34: 14/09/2026 | M34: 5 | N34: Medium | O34: Meeting | P34: Draft proposal shared
A35: EMB-034 | B35: Cambodia | C35: Asia-Pacific | D35: Mei Silva | E35: Counsellor (Public Affairs) | F35: mei.silva@cambodia.embassy.example | G35: +91 11 8391 8276 | H35: In Discussion | J35: 46097 | K35: 46299 | L35: 46328 | M35: 3 | N35: Low | O35: Email | P35: Embassy declined further participation
A36: EMB-035 | B36: UAE | C36: Middle East & North Africa | D36: Leila Nguyen | E36: Second Secretary | F36: leila.nguyen@unitedarabem.embassy.example | G36: +91 11 5805 7803 | H36: On Hold | I36: Arjun Mehta | J36: 45720 | K36: 46294 | L36: 46395 | M36: 4 | N36: Low | O36: Email | P36: Awaiting HQ approval
A37: EMB-036 | B37: Saudi Arabia | C37: Middle East & North Africa | D37: Nadia Nguyen | E37: First Secretary (Political) | F37: nadia.nguyen@saudiarabia.embassy.example | G37: +91 11 8085 3867 | H37: Meeting Scheduled | I37: Rahul Verma | J37: 45687 | K37: 46282 | L37: 46301 | M37: 8 | N37: High | O37: Official Letter | P37: Meeting with Ambassador pending
A38: EMB-037 | B38: Qatar | C38: Middle East & North Africa | D38: Carla Haddad | E38: Cultural Attache | F38: carla.haddad@qatar.embassy.example | G38: +91 11 2298 3725 | H38: Engaged | I38: Sameer Khan | J38: 45814 | K38: 46287 | L38: 46306 | M38: 16 | N38: High | O38: Meeting | P38: Active collaboration
A39: EMB-038 | B39: Kuwait | C39: Middle East & North Africa | D39: Yuki Zhang | E39: Second Secretary | F39: yuki.zhang@kuwait.embassy.example | G39: +91 99992 48005 | H39: Initial Contact Made | I39: Rahul Verma | J39: 45771 | K39: 46332 | L39: 46308 | M39: 2 | N39: Low | O39: Official Letter | P39: Note verbale sent
A40: EMB-039 | B40: Oman | C40: Middle East & North Africa | D40: Amara Rossi | E40: Press & Information Officer | F40: amara.rossi@oman.embassy.example | G40: +91 11 2135 7164 | H40: In Discussion | J40: 45928 | K40: 46280 | L40: 46320 | M40: 5 | O40: Meeting | P40: Reviewing MoU wording
...

Sheet Data Quality Review.
A1: Issue ID | B1: Category | C1: Excel Row(s) | D1: Field | E1: Current Value / Issue | F1: Severity | G1: Recommended Fix
A2: DQ001 | B2: Embassy ID | C2: 61 | D2: Embassy ID | E2: Blank | F2: High | G2: Verify the correct Embassy ID from the source database and enter it
A3: DQ002 | B3: Embassy ID | C3: 64 | D3: Embassy ID | E3: Blank | F3: High | G3: Verify the correct Embassy ID from the source database and enter it
A4: DQ003 | B4: Duplicate Record | C4: 11, 87 | D4: Embassy ID | E4: EMB-010 appears twice | F4: High | G4: Verify both records, retain one canonical record and remove/merge the duplicate
A5: DQ004 | B5: Duplicate Record | C5: 38, 89 | D5: Embassy ID | E5: EMB-037 appears twice; Last Contact Date differs | F5: High | G5: Verify the correct latest information, merge the records and remove the duplicate
A6: DQ005 | B6: Duplicate Record | C6: 52, 88 | D6: Embassy ID | E6: EMB-051 appears twice | F6: High | G6: Verify both records, retain one canonical record and remove/merge the duplicate
A7: DQ006 | B7: Duplicate Record | C7: 67, 86 | D7: Embassy ID | E7: EMB-066 appears twice | F7: High | G7: Verify both records, retain one canonical record and remove/merge the duplicate
A8: DQ007 | B8: Country Formatting | C8: 2 | D8: Country | E8: france | F8: Medium | G8: Standardise to France
A9: DQ008 | B9: Country Formatting | C9: 3 | D9: Country | E9: Leading space before Germany | F9: Low | G9: Remove leading/trailing spaces
A10: DQ009 | B10: Country Formatting | C10: 22 | D10: Country | E10: Japan has trailing space | F10: Low | G10: Remove leading/trailing spaces
A11: DQ010 | B11: Country Formatting | C11: 90 | D11: Country | E11: Mexico has trailing space | F11: Low | G11: Remove leading/trailing spaces
A12: DQ011 | B12: Country Formatting | C12: 92 | D12: Country | E12: GHANA | F12: Low | G12: Standardise capitalisation to Ghana
A13: DQ012 | B13: Region Missing | C13: 4 | D13: Region | E13: Blank | F13: High | G13: Populate from the authoritative regional classification
A14: DQ013 | B14: Region Missing | C14: 18 | D14: Region | E14: Blank | F14: High | G14: Populate from the authoritative regional classification
A15: DQ014 | B15: Region Missing | C15: 22 | D15: Region | E15: Blank | F15: High | G15: Populate from the authoritative regional classification
A16: DQ015 | B16: Region Missing | C16: 44 | D16: Region | E16: Blank | F16: High | G16: Populate from the authoritative regional classification
A17: DQ016 | B17: Region Missing | C17: 72 | D17: Region | E17: Blank | F17: High | G17: Populate from the authoritative regional classification
A18: DQ017 | B18: Region Inconsistency | C18: 16, 19 | D18: Region | E18: europe | F18: Medium | G18: Standardise to Europe
A19: DQ018 | B19: Region Inconsistency | C19: 37 | D19: Region | E19: MENA | F19: Medium | G19: Standardise to Middle East & North Africa if that is the approved organisational label
A20: DQ019 | B20: Region Inconsistency | C20: 51, 53, 58 | D20: Region | E20: Sub Saharan Africa | F20: Medium | G20: Standardise to Sub-Saharan Africa if that is the approved organisational label
A21: DQ020 | B21: Region Inconsistency | C21: 65, 70 | D21: Region | E21: N. America | F21: Medium | G21: Standardise to the approved regional label, e.g. Americas
A22: DQ021 | B22: Region Classification | C22: 46 | D22: Region | E22: Egypt classified as Sub-Saharan Africa | F22: High | G22: Verify against the organisation's official regional classification
A23: DQ022 | B23: Region Classification | C23: 83 | D23: Region | E23: Kazakhstan classified as Asia-Pacific | F23: High | G23: Verify against the organisation's official regional classification
A24: DQ023 | B24: Contact Name Formatting | C24: 26 | D24: Contact Person | E24: Leading/trailing spaces around Nadia Tanaka | F24: Low | G24: Apply TRIM/cleaning and remove extra spaces
A25: DQ024 | B25: Contact Name Formatting | C25: 59 | D25: Contact Person | E25: Leading/trailing spaces around Chen Khalil | F25: Low | G25: Apply TRIM/cleaning and remove extra spaces
A26: DQ025 | B26: Contact Name Formatting | C26: 65 | D26: Contact Person | E26: Leading/trailing spaces around Diego Mensah | F26: Low | G26: Apply TRIM/cleaning and remove extra spaces
A27: DQ026 | B27: Contact Name Formatting | C27: 67 | D27: Contact Person | E27: Leading/trailing spaces around Amara Kim | F27: Low | G27: Apply TRIM/cleaning and remove extra spaces
A28: DQ027 | B28: Contact Name Formatting | C28: 83 | D28: Contact Person | E28: Leading/trailing spaces around Amara Alvarez | F28: Low | G28: Apply TRIM/cleaning and remove extra spaces
A29: DQ028 | B29: Contact Name Formatting | C29: 86 | D29: Contact Person | E29: Leading/trailing spaces around Amara Kim | F29: Low | G29: Apply TRIM/cleaning and remove extra spaces
A30: DQ029 | B30: Missing Owner | C30: 10, 25, 35, 40, 52, 60, 64, 68, 88 | D30: Owner | E30: Blank | F30: High | G30: Assign the correct owner from the authorised owner/source list; do not guess
A31: DQ030 | B31: Missing Email | C31: 10, 49, 58, 61, 70, 80, 82 | D31: Email | E31: Blank | F31: High | G31: Recover the correct email from the authoritative source
A32: DQ031 | B32: Invalid Email | C32: 34 | D32: Email | E32: stefan.mensah@myanmar | F32: High | G32: Verify and enter the complete valid email address
A33: DQ032 | B33: Invalid Email | C33: 50 | D33: Email | E33: pavel.rossi.southafrica.embassy.example | F33: High | G33: Correct the missing @/email structure using the source record
A34: DQ033 | B34: Invalid Email | C34: 64 | D34: Email | E34: aisha.novak.unitedstates.embassy.example | F34: High | G34: Correct the missing @/email structure using the source record
A35: DQ034 | B35: Invalid Email | C35: 65 | D35: Email | E35: diego.mensah@canada | F35: High | G35: Verify and enter the complete valid email address
A36: DQ035 | B36: Invalid Email | C36: 67 | D36: Email | E36: amara.kim.brazil.embassy.example | F36: High | G36: Correct the missing @/email structure using the source record
A37: DQ036 | B37: Invalid Email | C37: 68 | D37: Email | E37: sofia.petrov.argentina.embassy.example | F37: High | G37: Correct the missing @/email structure using the source record
A38: DQ037 | B38: Invalid Email | C38: 86 | D38: Email | E38: amara.kim.brazil.embassy.example | F38: High | G38: Correct the missing @/email structure using the source record
A39: DQ038 | B39: Suspicious Email Domain | C39: Various | D39: Country Embassy Email Domain | E39: Several domains appear truncated, including czechrepubli, unitedkingdo and unitedarabem | F39: High | G39: Verify domains against the authoritative contact list rather than guessing
A40: DQ039 | B40: Missing Phone | C40: 17, 53, 60, 64, 75, 77, 78, 85 | D40: Phone | E40: Blank | F40: High | G40: Recover the correct phone number from the authoritative source
...
